2024-06-04 08:23:01,568 INFO    Thread-274 (_run_job):10852 [wandb_setup.py:_flush():76] Current SDK version is 0.16.6
2024-06-04 08:23:01,570 INFO    Thread-274 (_run_job):10852 [wandb_setup.py:_flush():76] Configure stats pid to 10852
2024-06-04 08:23:01,570 INFO    Thread-274 (_run_job):10852 [wandb_setup.py:_flush():76] Loading settings from C:\Users\lukea\.config\wandb\settings
2024-06-04 08:23:01,570 INFO    Thread-274 (_run_job):10852 [wandb_setup.py:_flush():76] Loading settings from G:\My Drive\MSc\0_Project\MSc_Project\wandb\settings
2024-06-04 08:23:01,570 INFO    Thread-274 (_run_job):10852 [wandb_setup.py:_flush():76] Loading settings from environment variables: {'project': 'MSc Project', 'entity': 'llalderson', 'root_dir': 'G:\\My Drive\\MSc\\0_Project\\MSc_Project', 'run_id': 'c9wxe9ow', 'sweep_param_path': 'G:\\My Drive\\MSc\\0_Project\\MSc_Project\\wandb\\sweep-3c3kmrdb\\config-c9wxe9ow.yaml', 'sweep_id': '3c3kmrdb'}
2024-06-04 08:23:01,570 INFO    Thread-274 (_run_job):10852 [wandb_setup.py:_flush():76] Applying setup settings: {'_disable_service': False}
2024-06-04 08:23:01,570 INFO    Thread-274 (_run_job):10852 [wandb_setup.py:_flush():76] Inferring run settings from compute environment: {'program_relpath': 'main.py', 'program_abspath': 'g:\\my drive\\msc\\0_project\\msc_project\\main.py', 'program': 'g:\\my drive\\msc\\0_project\\msc_project\\main.py'}
2024-06-04 08:23:01,570 INFO    Thread-274 (_run_job):10852 [wandb_setup.py:_flush():76] Applying login settings: {}
2024-06-04 08:23:01,571 INFO    Thread-274 (_run_job):10852 [wandb_init.py:_log_setup():521] Logging user logs to G:\My Drive\MSc\0_Project\MSc_Project\wandb\run-20240604_082301-c9wxe9ow\logs\debug.log
2024-06-04 08:23:01,571 INFO    Thread-274 (_run_job):10852 [wandb_init.py:_log_setup():522] Logging internal logs to G:\My Drive\MSc\0_Project\MSc_Project\wandb\run-20240604_082301-c9wxe9ow\logs\debug-internal.log
2024-06-04 08:23:01,571 INFO    Thread-274 (_run_job):10852 [wandb_init.py:init():561] calling init triggers
2024-06-04 08:23:01,572 INFO    Thread-274 (_run_job):10852 [wandb_init.py:init():568] wandb.init called with sweep_config: {'bs': 32, 'epochs': 3, 'lr': 0.0001, 'subset_size': 1}
config: {}
2024-06-04 08:23:01,572 INFO    Thread-274 (_run_job):10852 [wandb_init.py:init():611] starting backend
2024-06-04 08:23:01,572 INFO    Thread-274 (_run_job):10852 [wandb_init.py:init():615] setting up manager
2024-06-04 08:23:01,584 INFO    Thread-274 (_run_job):10852 [backend.py:_multiprocessing_setup():105] multiprocessing start_methods=spawn, using: spawn
2024-06-04 08:23:01,585 INFO    Thread-274 (_run_job):10852 [wandb_init.py:init():623] backend started and connected
2024-06-04 08:23:01,608 INFO    Thread-274 (_run_job):10852 [wandb_run.py:_config_callback():1347] config_cb None None {'bs': 32, 'epochs': 3, 'lr': 0.0001, 'subset_size': 1}
2024-06-04 08:23:01,609 INFO    Thread-274 (_run_job):10852 [wandb_init.py:init():715] updated telemetry
2024-06-04 08:23:01,663 INFO    Thread-274 (_run_job):10852 [wandb_init.py:init():748] communicating run to backend with 90.0 second timeout
2024-06-04 08:23:02,323 INFO    Thread-274 (_run_job):10852 [wandb_run.py:_on_init():2357] communicating current version
2024-06-04 08:23:02,868 INFO    Thread-274 (_run_job):10852 [wandb_run.py:_on_init():2366] got version response upgrade_message: "wandb version 0.17.0 is available!  To upgrade, please run:\n $ pip install wandb --upgrade"

2024-06-04 08:23:02,869 INFO    Thread-274 (_run_job):10852 [wandb_init.py:init():799] starting run threads in backend
2024-06-04 08:23:03,326 INFO    Thread-274 (_run_job):10852 [wandb_run.py:_console_start():2335] atexit reg
2024-06-04 08:23:03,327 INFO    Thread-274 (_run_job):10852 [wandb_run.py:_redirect():2190] redirect: wrap_raw
2024-06-04 08:23:03,328 INFO    Thread-274 (_run_job):10852 [wandb_run.py:_redirect():2255] Wrapping output streams.
2024-06-04 08:23:03,328 INFO    Thread-274 (_run_job):10852 [wandb_run.py:_redirect():2280] Redirects installed.
2024-06-04 08:23:03,329 INFO    Thread-274 (_run_job):10852 [wandb_init.py:init():842] run started, returning control to user process
2024-06-04 08:54:42,358 INFO    Thread-15 (_heartbeat):10852 [retry.py:__call__():172] Retry attempt failed:
Traceback (most recent call last):
  File "C:\Users\lukea\anaconda3\envs\diss\Lib\site-packages\urllib3\connection.py", line 203, in _new_conn
    sock = connection.create_connection(
           ^^^^^^^^^^^^^^^^^^^^^^^^^^^^^
  File "C:\Users\lukea\anaconda3\envs\diss\Lib\site-packages\urllib3\util\connection.py", line 60, in create_connection
    for res in socket.getaddrinfo(host, port, family, socket.SOCK_STREAM):
               ^^^^^^^^^^^^^^^^^^^^^^^^^^^^^^^^^^^^^^^^^^^^^^^^^^^^^^^^^^
  File "C:\Users\lukea\anaconda3\envs\diss\Lib\socket.py", line 963, in getaddrinfo
    for res in _socket.getaddrinfo(host, port, family, type, proto, flags):
               ^^^^^^^^^^^^^^^^^^^^^^^^^^^^^^^^^^^^^^^^^^^^^^^^^^^^^^^^^^^
socket.gaierror: [Errno 11001] getaddrinfo failed

The above exception was the direct cause of the following exception:

Traceback (most recent call last):
  File "C:\Users\lukea\anaconda3\envs\diss\Lib\site-packages\urllib3\connectionpool.py", line 790, in urlopen
    response = self._make_request(
               ^^^^^^^^^^^^^^^^^^^
  File "C:\Users\lukea\anaconda3\envs\diss\Lib\site-packages\urllib3\connectionpool.py", line 491, in _make_request
    raise new_e
  File "C:\Users\lukea\anaconda3\envs\diss\Lib\site-packages\urllib3\connectionpool.py", line 467, in _make_request
    self._validate_conn(conn)
  File "C:\Users\lukea\anaconda3\envs\diss\Lib\site-packages\urllib3\connectionpool.py", line 1096, in _validate_conn
    conn.connect()
  File "C:\Users\lukea\anaconda3\envs\diss\Lib\site-packages\urllib3\connection.py", line 611, in connect
    self.sock = sock = self._new_conn()
                       ^^^^^^^^^^^^^^^^
  File "C:\Users\lukea\anaconda3\envs\diss\Lib\site-packages\urllib3\connection.py", line 210, in _new_conn
    raise NameResolutionError(self.host, self, e) from e
urllib3.exceptions.NameResolutionError: <urllib3.connection.HTTPSConnection object at 0x000001C9C509D0A0>: Failed to resolve 'api.wandb.ai' ([Errno 11001] getaddrinfo failed)

The above exception was the direct cause of the following exception:

Traceback (most recent call last):
  File "C:\Users\lukea\anaconda3\envs\diss\Lib\site-packages\requests\adapters.py", line 486, in send
    resp = conn.urlopen(
           ^^^^^^^^^^^^^
  File "C:\Users\lukea\anaconda3\envs\diss\Lib\site-packages\urllib3\connectionpool.py", line 844, in urlopen
    retries = retries.increment(
              ^^^^^^^^^^^^^^^^^^
  File "C:\Users\lukea\anaconda3\envs\diss\Lib\site-packages\urllib3\util\retry.py", line 515, in increment
    raise MaxRetryError(_pool, url, reason) from reason  # type: ignore[arg-type]
    ^^^^^^^^^^^^^^^^^^^^^^^^^^^^^^^^^^^^^^^^^^^^^^^^^^^
urllib3.exceptions.MaxRetryError: HTTPSConnectionPool(host='api.wandb.ai', port=443): Max retries exceeded with url: /graphql (Caused by NameResolutionError("<urllib3.connection.HTTPSConnection object at 0x000001C9C509D0A0>: Failed to resolve 'api.wandb.ai' ([Errno 11001] getaddrinfo failed)"))

During handling of the above exception, another exception occurred:

Traceback (most recent call last):
  File "C:\Users\lukea\anaconda3\envs\diss\Lib\site-packages\wandb\sdk\lib\retry.py", line 131, in __call__
    result = self._call_fn(*args, **kwargs)
             ^^^^^^^^^^^^^^^^^^^^^^^^^^^^^^
  File "C:\Users\lukea\anaconda3\envs\diss\Lib\site-packages\wandb\sdk\internal\internal_api.py", line 369, in execute
    return self.client.execute(*args, **kwargs)  # type: ignore
           ^^^^^^^^^^^^^^^^^^^^^^^^^^^^^^^^^^^^
  File "C:\Users\lukea\anaconda3\envs\diss\Lib\site-packages\wandb\vendor\gql-0.2.0\wandb_gql\client.py", line 52, in execute
    result = self._get_result(document, *args, **kwargs)
             ^^^^^^^^^^^^^^^^^^^^^^^^^^^^^^^^^^^^^^^^^^^
  File "C:\Users\lukea\anaconda3\envs\diss\Lib\site-packages\wandb\vendor\gql-0.2.0\wandb_gql\client.py", line 60, in _get_result
    return self.transport.execute(document, *args, **kwargs)
           ^^^^^^^^^^^^^^^^^^^^^^^^^^^^^^^^^^^^^^^^^^^^^^^^^
  File "C:\Users\lukea\anaconda3\envs\diss\Lib\site-packages\wandb\sdk\lib\gql_request.py", line 58, in execute
    request = self.session.post(self.url, **post_args)
              ^^^^^^^^^^^^^^^^^^^^^^^^^^^^^^^^^^^^^^^^
  File "C:\Users\lukea\anaconda3\envs\diss\Lib\site-packages\requests\sessions.py", line 637, in post
    return self.request("POST", url, data=data, json=json, **kwargs)
           ^^^^^^^^^^^^^^^^^^^^^^^^^^^^^^^^^^^^^^^^^^^^^^^^^^^^^^^^^
  File "C:\Users\lukea\anaconda3\envs\diss\Lib\site-packages\requests\sessions.py", line 589, in request
    resp = self.send(prep, **send_kwargs)
           ^^^^^^^^^^^^^^^^^^^^^^^^^^^^^^
  File "C:\Users\lukea\anaconda3\envs\diss\Lib\site-packages\requests\sessions.py", line 703, in send
    r = adapter.send(request, **kwargs)
        ^^^^^^^^^^^^^^^^^^^^^^^^^^^^^^^
  File "C:\Users\lukea\anaconda3\envs\diss\Lib\site-packages\requests\adapters.py", line 519, in send
    raise ConnectionError(e, request=request)
requests.exceptions.ConnectionError: HTTPSConnectionPool(host='api.wandb.ai', port=443): Max retries exceeded with url: /graphql (Caused by NameResolutionError("<urllib3.connection.HTTPSConnection object at 0x000001C9C509D0A0>: Failed to resolve 'api.wandb.ai' ([Errno 11001] getaddrinfo failed)"))
