Starting Sweep: Batch Size: 64, Learning Rate: 0.0001
Making datasets and defining subsets
Training: 60000 -> 600
Testing: 10000 -> 100
Making Dataloaders
Defining network
2024-06-14 14:15:24.447599
Scaler Value: 0.013513513513513514
Training - 2024-06-14 14:15:24.448095
[1/1, 1/10] Training Loss: 0.0673 - Iteration Time: 0:00:01.834254
[1/1, 2/10] Training Loss: 0.0683 - Iteration Time: 0:00:01.343950
[1/1, 3/10] Training Loss: 0.0697 - Iteration Time: 0:00:01.320283
[1/1, 4/10] Training Loss: 0.0707 - Iteration Time: 0:00:01.267588
[1/1, 5/10] Training Loss: 0.0676 - Iteration Time: 0:00:01.285060
[1/1, 6/10] Training Loss: 0.0686 - Iteration Time: 0:00:01.340241
[1/1, 7/10] Training Loss: 0.0685 - Iteration Time: 0:00:01.425884
[1/1, 8/10] Training Loss: 0.0675 - Iteration Time: 0:00:01.398431
[1/1, 9/10] Training Loss: 0.0653 - Iteration Time: 0:00:01.325212
[1/1, 10/10] Training Loss: 0.0682 - Iteration Time: 0:00:01.385481
Testing - 2024-06-14 14:15:48.395103
[1/1, 1/2]
[1/1, 2/2]
Testing Loss: 0.0683 - Epoch Time: 0:00:42.039041
Training and Testing Finished - Time: 0:00:42.040034
Assembling test data for t-sne projection
{'rate_on': 75. * hertz, 'rate_off': 1. * hertz, 'total_time': 200. * msecond, 'bin_size': 1. * msecond}
Code Layer Shape: torch.Size([64, 100])
-- 1/2 --
{'rate_on': 75. * hertz, 'rate_off': 1. * hertz, 'total_time': 200. * msecond, 'bin_size': 1. * msecond}
Code Layer Shape: torch.Size([36, 100])
-- 2/2 --
Plotting Results Grid
Plotting Spiking Input MNIST
Plotting Spiking Input MNIST Animation - 3
Exception ignored in: Exception in thread <function _ConnectionBase.__del__ at 0x0000021B1619CEA0>QueueFeederThread
:
Traceback (most recent call last):
  File "C:\Users\lukea\anaconda3\envs\diss\Lib\multiprocessing\connection.py", line 133, in __del__
Traceback (most recent call last):
  File "C:\Users\lukea\anaconda3\envs\diss\Lib\multiprocessing\queues.py", line 259, in _feed
    self._close()
reader_close()  File "C:\Users\lukea\anaconda3\envs\diss\Lib\multiprocessing\connection.py", line 282, in _close
  File "C:\Users\lukea\anaconda3\envs\diss\Lib\multiprocessing\connection.py", line 178, in close
    _CloseHandle(self._handle)
OSError: [WinError 6] The handle is invalid
self._close()
  File "C:\Users\lukea\anaconda3\envs\diss\Lib\multiprocessing\connection.py", line 282, in _close
    _CloseHandle(self._handle)
OSError: [WinError 6] The handle is invalid
During handling of the above exception, another exception occurred:
Traceback (most recent call last):
  File "C:\Users\lukea\anaconda3\envs\diss\Lib\threading.py", line 1073, in _bootstrap_inner
    self.run()
  File "C:\Users\lukea\anaconda3\envs\diss\Lib\site-packages\ipykernel\ipkernel.py", line 761, in run_closure
    _threading_Thread_run(self)
  File "C:\Users\lukea\anaconda3\envs\diss\Lib\threading.py", line 1010, in run
    self._target(*self._args, **self._kwargs)
  File "C:\Users\lukea\anaconda3\envs\diss\Lib\multiprocessing\queues.py", line 291, in _feed
    queue_sem.release()
ValueError: semaphore or lock released too many times
Plotting Spiking Output MNIST
Plotting Spiking Output MNIST Animation - 3
WARNING    C:\Users\lukea\anaconda3\envs\diss\Lib\site-packages\joblib\externals\loky\backend\context.py:136: UserWarning: Could not find the number of physical cores for the following reason:
found 0 physical cores < 1
Returning the number of logical cores instead. You can silence this warning by setting LOKY_MAX_CPU_COUNT to the number of cores you want to use.
  warnings.warn(
 [py.warnings]
  File "C:\Users\lukea\anaconda3\envs\diss\Lib\site-packages\joblib\externals\loky\backend\context.py", line 282, in _count_physical_cores
    raise ValueError(f"found {cpu_count_physical} physical cores < 1")
Applying t-SNE